Workbook
Name _Hlk168301166: Keterlambatan!$B$2

Sheet DATA
A1: Surat Tugas | B1: Nomor | C1: : | D1: B-1122/62130/KU.340/2026 | K1: Revisi 10 oleh Krishna Aji, ®2026. Untuk digunakan sebagai mestinya.
B2: Tanggal | C2: : | D2: 13 Agustus 2026
B3: Penandatangan ST | C3: : | D3: Restu Kristianto, S.Pi.
B4: Jabatan Penandatangan | C4: : | D4: Kepala BPS Kabupaten Murung Raya
B5: NIP Penandatangan | D5: 19780715 200212 1 006
B6: Nama Pegawai Perjadin | C6: : | D6: Luthfiani Nur Aisyah, S.Tr.Stat. | F6: pilih nama disini
B7: NIP Pegawai | D7: 20030629 202603 2 001
B8: Jabatan Pegawai | C8: : | D8: Pelaksana
B9: Pangkat/Golongan | C9: : | D9: Penata Muda / III/a
B10: Perihal | C10: : | D10: Pengawasan Pendataan Sakernas Agustus 2026 | F10: nama kegiatan
B11: Tujuan Tugas | C11: : | D11: Melakukan Pengawasan Pendataan Sakernas Agustus 2026 di Desa Juking Supan | F11: deskripsi kegiatan
B12: Waktu Pelaksanaan | C12: : | D12: 15 Agustus 2026 s.d. 15 Agustus 2026 | F12: harap tulis dengan penulisan sama, meskipun tanggal hanya satu hari
B13: Pembebanan | C13: : | D13: GG.2905.BMA.004.052.A.524113 | F13: sesuai dengan form permintaan BOS
A15: SPD | B15: Nomor | C15: : | D15: 231/62130/KU.340/2026 | F15: HARUS kosong apabila tidak ada SPD
B16: Tanggal | C16: : | D16: 13 Agustus 2026
B17: Angkutan | C17: : | D17: Kendaraan Air
B18: Tempat Berangkat | C18: : | D18: Kelurahan Beriwit
B19: Tempat Berangkat | C19: : | D19: Kabupaten Murung Raya
B20: Tempat Tujuan | C20: : | D20: Desa Juking Supan
B21: Tempat Tujuan | C21: : | D21: Kabupaten Murung Raya
B22: Lamanya | C22: : | D22: =_xlfn.CONCAT(E22," (",F22,")"," hari") -> 1 (satu) hari | E22: =E24-E23+1 -> 1 | F22: =IF(E22=0,".................................................",IF(E22<0,"minus ","")& SUBSTITUTE(TRIM(SUBSTITUTE(SUBSTITUTE(SUBSTITUTE(SUBSTITUTE(SUBSTITUTE(SUBSTITUTE(SUBSTITUTE(SUBSTITUTE(SUBSTITUTE(SUBSTITUTE(SUBSTITUTE(SUBSTITUTE(SUBSTITUTE(SUBSTITUTE(SUBSTITUTE(SUBSTITUTE(SUBSTITUTE(SUBSTITUTE(SUBSTITUTE(SUBSTITUTE(SUBSTITUTE(SUBSTITUTE(SUBSTITUTE(SUBSTITUTE( IF(--MID(TEXT(ABS(E22),"000000000000000"),1,3)=0,"",MID(TEXT(ABS(E22),"000000000000000"),1,1)&" ratus "&MID(TEXT(ABS(E22),"000000000000000"),2,1)&" puluh "&MID(TEXT(ABS(E22),"000000000000000"),3,1)&" trilyun ")& IF(--MID(TEXT(ABS(E22),"000000000000000"),4,3)=0,"",MID(TEXT(ABS(E22),"000000000000000"),4,1)&" ratus "&MID(TEXT(ABS(E22),"000000000000000"),5,1)&" puluh "&MID(TEXT(ABS(E22),"000000000000000"),6,1)&" milyar ")& IF(--MID(TEXT(ABS(E22),"000000000000000"),7,3)=0,"",MID(TEXT(ABS(E22),"000000000000000"),7,1)&" ratus "&MID(TEXT(ABS(E22),"000000000000000"),8,1)&" puluh "&MID(TEXT(ABS(E22),"000000000000000"),9,1)&" juta ")& IF(--MID(TEXT(ABS(E22),"000000000000000"),10,3)=0,"",IF(--MID(TEXT(ABS(E22),"000000000000000"),10,3)=1,"*",MID(TEXT(ABS(E22),"000000000000000"),10,1)&" ratus "&MID(TEXT(ABS(E22),"000000000000000"),11,1)&" puluh ")&MID(TEXT(ABS(E22),"000000000000000"),12,1)&" ribu ")& IF(--MID(TEXT(ABS(E22),"000000000000000"),13,3)=0,"",MID(TEXT(ABS(E22),"000000000000000"),13,1)&" ratus "&MID(TEXT(ABS(E22),"000000000000000"),14,1)&" puluh "&MID(TEXT(ABS(E22),"000000000000000"),15,1)),1,"satu"),2,"dua"),3,"tiga"),4,"empat"),5,"lima"),6,"enam"),7,"tujuh"),8,"delapan"),9,"sembilan"),"0 ratus",""),"0 puluh",""),"satu puluh 0","sepuluh"),"satu puluh satu","sebelas"),"satu puluh dua","dua belas"),"satu puluh tiga","tiga belas"),"satu puluh empat","empat belas"),"satu puluh lima","lima belas"),"satu puluh enam","enam belas"),"satu puluh tujuh","tujuh belas"),"satu puluh delapan","delapan belas"),"satu puluh sembilan","sembilan belas"),"satu ratus","seratus"),"*satu ribu","seribu"),0,""))," "," ")) -> satu
B23: Tgl Berangkat | C23: : | D23: =TRIM(LEFT(D12,SEARCH("s.d.",D12)-1)) -> 15 Agustus 2026 | E23: =DATE(RIGHT(D23,4),MATCH(MID(D23,FIND(" ",D23)+1,FIND(" ",D23,FIND(" ",D23)+1)-FIND(" ",D23)-1),DB!$B$48:$B$59,0),LEFT(D23,FIND(" ",D23)-1)) -> 46249
B24: Tgl Kembali | C24: : | D24: =TRIM(MID(D12,SEARCH("s.d.",D12)+4,LEN(D12))) -> 15 Agustus 2026 | E24: =DATE(RIGHT(D24,4),MATCH(MID(D24,FIND(" ",D24)+1,FIND(" ",D24,FIND(" ",D24)+1)-FIND(" ",D24)-1),DB!$B$48:$B$59,0),LEFT(D24,FIND(" ",D24)-1)) -> 46249
B25: Penandatangan SPD | C25: : | D25: Khoirul Anwar, S.Tr.Stat.
B26: Jabatan Penandatangan | C26: : | D26: Pejabat Pembuat Komitmen
B27: NIP Penandatangan | C27: : | D27: =VLOOKUP(MATCH(D25,DB!$D$2:$D$14,0),DB!$A$2:$H$14,3) -> 19990307 202104 1 001
A29: Kuitansi | B29: Tanggal | C29: : | D29: 18 Agustus 2026 | F29: tulisin tanggal pas bikin
B30: Rate UH | C30: : | D30: 140000 | F30: sesuaikan dengan rate harian
B31: Transport | C31: : | D31: 0 | E31: =IF(D31=0,"nol",IF(D31<0,"minus ","")& SUBSTITUTE(TRIM(SUBSTITUTE(SUBSTITUTE(SUBSTITUTE(SUBSTITUTE(SUBSTITUTE(SUBSTITUTE(SUBSTITUTE(SUBSTITUTE(SUBSTITUTE(SUBSTITUTE(SUBSTITUTE(SUBSTITUTE(SUBSTITUTE(SUBSTITUTE(SUBSTITUTE(SUBSTITUTE(SUBSTITUTE(SUBSTITUTE(SUBSTITUTE(SUBSTITUTE(SUBSTITUTE(SUBSTITUTE(SUBSTITUTE(SUBSTITUTE( IF(--MID(TEXT(ABS(D31),"000000000000000"),1,3)=0,"",MID(TEXT(ABS(D31),"000000000000000"),1,1)&" ratus "&MID(TEXT(ABS(D31),"000000000000000"),2,1)&" puluh "&MID(TEXT(ABS(D31),"000000000000000"),3,1)&" trilyun ")& IF(--MID(TEXT(ABS(D31),"000000000000000"),4,3)=0,"",MID(TEXT(ABS(D31),"000000000000000"),4,1)&" ratus "&MID(TEXT(ABS(D31),"000000000000000"),5,1)&" puluh "&MID(TEXT(ABS(D31),"000000000000000"),6,1)&" milyar ")& IF(--MID(TEXT(ABS(D31),"000000000000000"),7,3)=0,"",MID(TEXT(ABS(D31),"000000000000000"),7,1)&" ratus "&MID(TEXT(ABS(D31),"000000000000000"),8,1)&" puluh "&MID(TEXT(ABS(D31),"000000000000000"),9,1)&" juta ")& IF(--MID(TEXT(ABS(D31),"000000000000000"),10,3)=0,"",IF(--MID(TEXT(ABS(D31),"000000000000000"),10,3)=1,"*",MID(TEXT(ABS(D31),"000000000000000"),10,1)&" ratus "&MID(TEXT(ABS(D31),"000000000000000"),11,1)&" puluh ")&MID(TEXT(ABS(D31),"000000000000000"),12,1)&" ribu ")& IF(--MID(TEXT(ABS(D31),"000000000000000"),13,3)=0,"",MID(TEXT(ABS(D31),"000000000000000"),13,1)&" ratus "&MID(TEXT(ABS(D31),"000000000000000"),14,1)&" puluh "&MID(TEXT(ABS(D31),"000000000000000"),15,1)),1,"satu"),2,"dua"),3,"tiga"),4,"empat"),5,"lima"),6,"enam"),7,"tujuh"),8,"delapan"),9,"sembilan"),"0 ratus",""),"0 puluh",""),"satu puluh 0","sepuluh"),"satu puluh satu","sebelas"),"satu puluh dua","dua belas"),"satu puluh tiga","tiga belas"),"satu puluh empat","empat belas"),"satu puluh lima","lima belas"),"satu puluh enam","enam belas"),"satu puluh tujuh","tujuh belas"),"satu puluh delapan","delapan belas"),"satu puluh sembilan","sembilan belas"),"satu ratus","seratus"),"*satu ribu","seribu"),0,""))," "," ")) & " rupiah" -> nol rupiah | F31: =REPLACE(E31,1,1,UPPER(LEFT(E31))) -> Nol rupiah
B32: UH | C32: : | D32: =D30*E22 -> 140000 | E32: =IF(D32=0,"nol",IF(D32<0,"minus ","")& SUBSTITUTE(TRIM(SUBSTITUTE(SUBSTITUTE(SUBSTITUTE(SUBSTITUTE(SUBSTITUTE(SUBSTITUTE(SUBSTITUTE(SUBSTITUTE(SUBSTITUTE(SUBSTITUTE(SUBSTITUTE(SUBSTITUTE(SUBSTITUTE(SUBSTITUTE(SUBSTITUTE(SUBSTITUTE(SUBSTITUTE(SUBSTITUTE(SUBSTITUTE(SUBSTITUTE(SUBSTITUTE(SUBSTITUTE(SUBSTITUTE(SUBSTITUTE( IF(--MID(TEXT(ABS(D32),"000000000000000"),1,3)=0,"",MID(TEXT(ABS(D32),"000000000000000"),1,1)&" ratus "&MID(TEXT(ABS(D32),"000000000000000"),2,1)&" puluh "&MID(TEXT(ABS(D32),"000000000000000"),3,1)&" trilyun ")& IF(--MID(TEXT(ABS(D32),"000000000000000"),4,3)=0,"",MID(TEXT(ABS(D32),"000000000000000"),4,1)&" ratus "&MID(TEXT(ABS(D32),"000000000000000"),5,1)&" puluh "&MID(TEXT(ABS(D32),"000000000000000"),6,1)&" milyar ")& IF(--MID(TEXT(ABS(D32),"000000000000000"),7,3)=0,"",MID(TEXT(ABS(D32),"000000000000000"),7,1)&" ratus "&MID(TEXT(ABS(D32),"000000000000000"),8,1)&" puluh "&MID(TEXT(ABS(D32),"000000000000000"),9,1)&" juta ")& IF(--MID(TEXT(ABS(D32),"000000000000000"),10,3)=0,"",IF(--MID(TEXT(ABS(D32),"000000000000000"),10,3)=1,"*",MID(TEXT(ABS(D32),"000000000000000"),10,1)&" ratus "&MID(TEXT(ABS(D32),"000000000000000"),11,1)&" puluh ")&MID(TEXT(ABS(D32),"000000000000000"),12,1)&" ribu ")& IF(--MID(TEXT(ABS(D32),"000000000000000"),13,3)=0,"",MID(TEXT(ABS(D32),"000000000000000"),13,1)&" ratus "&MID(TEXT(ABS(D32),"000000000000000"),14,1)&" puluh "&MID(TEXT(ABS(D32),"000000000000000"),15,1)),1,"satu"),2,"dua"),3,"tiga"),4,"empat"),5,"lima"),6,"enam"),7,"tujuh"),8,"delapan"),9,"sembilan"),"0 ratus",""),"0 puluh",""),"satu puluh 0","sepuluh"),"satu puluh satu","sebelas"),"satu puluh dua","dua belas"),"satu puluh tiga","tiga belas"),"satu puluh empat","empat belas"),"satu puluh lima","lima belas"),"satu puluh enam","enam belas"),"satu puluh tujuh","tujuh belas"),"satu puluh delapan","delapan belas"),"satu puluh sembilan","sembilan belas"),"satu ratus","seratus"),"*satu ribu","seribu"),0,""))," "," ")) & " rupiah" -> seratus empat puluh ribu rupiah | F32: =REPLACE(E32,1,1,UPPER(LEFT(E32))) -> Seratus empat puluh ribu rupiah
B33: Uang Penginapan | C33: : | D33: 0 | E33: =IF(D33=0,"nol",IF(D33<0,"minus ","")& SUBSTITUTE(TRIM(SUBSTITUTE(SUBSTITUTE(SUBSTITUTE(SUBSTITUTE(SUBSTITUTE(SUBSTITUTE(SUBSTITUTE(SUBSTITUTE(SUBSTITUTE(SUBSTITUTE(SUBSTITUTE(SUBSTITUTE(SUBSTITUTE(SUBSTITUTE(SUBSTITUTE(SUBSTITUTE(SUBSTITUTE(SUBSTITUTE(SUBSTITUTE(SUBSTITUTE(SUBSTITUTE(SUBSTITUTE(SUBSTITUTE(SUBSTITUTE( IF(--MID(TEXT(ABS(D33),"000000000000000"),1,3)=0,"",MID(TEXT(ABS(D33),"000000000000000"),1,1)&" ratus "&MID(TEXT(ABS(D33),"000000000000000"),2,1)&" puluh "&MID(TEXT(ABS(D33),"000000000000000"),3,1)&" trilyun ")& IF(--MID(TEXT(ABS(D33),"000000000000000"),4,3)=0,"",MID(TEXT(ABS(D33),"000000000000000"),4,1)&" ratus "&MID(TEXT(ABS(D33),"000000000000000"),5,1)&" puluh "&MID(TEXT(ABS(D33),"000000000000000"),6,1)&" milyar ")& IF(--MID(TEXT(ABS(D33),"000000000000000"),7,3)=0,"",MID(TEXT(ABS(D33),"000000000000000"),7,1)&" ratus "&MID(TEXT(ABS(D33),"000000000000000"),8,1)&" puluh "&MID(TEXT(ABS(D33),"000000000000000"),9,1)&" juta ")& IF(--MID(TEXT(ABS(D33),"000000000000000"),10,3)=0,"",IF(--MID(TEXT(ABS(D33),"000000000000000"),10,3)=1,"*",MID(TEXT(ABS(D33),"000000000000000"),10,1)&" ratus "&MID(TEXT(ABS(D33),"000000000000000"),11,1)&" puluh ")&MID(TEXT(ABS(D33),"000000000000000"),12,1)&" ribu ")& IF(--MID(TEXT(ABS(D33),"000000000000000"),13,3)=0,"",MID(TEXT(ABS(D33),"000000000000000"),13,1)&" ratus "&MID(TEXT(ABS(D33),"000000000000000"),14,1)&" puluh "&MID(TEXT(ABS(D33),"000000000000000"),15,1)),1,"satu"),2,"dua"),3,"tiga"),4,"empat"),5,"lima"),6,"enam"),7,"tujuh"),8,"delapan"),9,"sembilan"),"0 ratus",""),"0 puluh",""),"satu puluh 0","sepuluh"),"satu puluh satu","sebelas"),"satu puluh dua","dua belas"),"satu puluh tiga","tiga belas"),"satu puluh empat","empat belas"),"satu puluh lima","lima belas"),"satu puluh enam","enam belas"),"satu puluh tujuh","tujuh belas"),"satu puluh delapan","delapan belas"),"satu puluh sembilan","sembilan belas"),"satu ratus","seratus"),"*satu ribu","seribu"),0,""))," "," ")) & " rupiah" -> nol rupiah | F33: =REPLACE(E33,1,1,UPPER(LEFT(E33))) -> Nol rupiah
B34: Pengeluaran Riil | C34: : | D34: =Riil!I20 -> 350000 | E34: =IF(D34=0,"nol",IF(D34<0,"minus ","")& SUBSTITUTE(TRIM(SUBSTITUTE(SUBSTITUTE(SUBSTITUTE(SUBSTITUTE(SUBSTITUTE(SUBSTITUTE(SUBSTITUTE(SUBSTITUTE(SUBSTITUTE(SUBSTITUTE(SUBSTITUTE(SUBSTITUTE(SUBSTITUTE(SUBSTITUTE(SUBSTITUTE(SUBSTITUTE(SUBSTITUTE(SUBSTITUTE(SUBSTITUTE(SUBSTITUTE(SUBSTITUTE(SUBSTITUTE(SUBSTITUTE(SUBSTITUTE( IF(--MID(TEXT(ABS(D34),"000000000000000"),1,3)=0,"",MID(TEXT(ABS(D34),"000000000000000"),1,1)&" ratus "&MID(TEXT(ABS(D34),"000000000000000"),2,1)&" puluh "&MID(TEXT(ABS(D34),"000000000000000"),3,1)&" trilyun ")& IF(--MID(TEXT(ABS(D34),"000000000000000"),4,3)=0,"",MID(TEXT(ABS(D34),"000000000000000"),4,1)&" ratus "&MID(TEXT(ABS(D34),"000000000000000"),5,1)&" puluh "&MID(TEXT(ABS(D34),"000000000000000"),6,1)&" milyar ")& IF(--MID(TEXT(ABS(D34),"000000000000000"),7,3)=0,"",MID(TEXT(ABS(D34),"000000000000000"),7,1)&" ratus "&MID(TEXT(ABS(D34),"000000000000000"),8,1)&" puluh "&MID(TEXT(ABS(D34),"000000000000000"),9,1)&" juta ")& IF(--MID(TEXT(ABS(D34),"000000000000000"),10,3)=0,"",IF(--MID(TEXT(ABS(D34),"000000000000000"),10,3)=1,"*",MID(TEXT(ABS(D34),"000000000000000"),10,1)&" ratus "&MID(TEXT(ABS(D34),"000000000000000"),11,1)&" puluh ")&MID(TEXT(ABS(D34),"000000000000000"),12,1)&" ribu ")& IF(--MID(TEXT(ABS(D34),"000000000000000"),13,3)=0,"",MID(TEXT(ABS(D34),"000000000000000"),13,1)&" ratus "&MID(TEXT(ABS(D34),"000000000000000"),14,1)&" puluh "&MID(TEXT(ABS(D34),"000000000000000"),15,1)),1,"satu"),2,"dua"),3,"tiga"),4,"empat"),5,"lima"),6,"enam"),7,"tujuh"),8,"delapan"),9,"sembilan"),"0 ratus",""),"0 puluh",""),"satu puluh 0","sepuluh"),"satu puluh satu","sebelas"),"satu puluh dua","dua belas"),"satu puluh tiga","tiga belas"),"satu puluh empat","empat belas"),"satu puluh lima","lima belas"),"satu puluh enam","enam belas"),"satu puluh tujuh","tujuh belas"),"satu puluh delapan","delapan belas"),"satu puluh sembilan","sembilan belas"),"satu ratus","seratus"),"*satu ribu","seribu"),0,""))," "," ")) & " rupiah" -> tiga ratus lima puluh ribu rupiah | F34: =REPLACE(E34,1,1,UPPER(LEFT(E34))) -> Tiga ratus lima puluh ribu rupiah
B35: Nilai Total | C35: : | D35: =SUM(D31:D34) -> 490000 | E35: =IF(D35=0,"nol",IF(D35<0,"minus ","")& SUBSTITUTE(TRIM(SUBSTITUTE(SUBSTITUTE(SUBSTITUTE(SUBSTITUTE(SUBSTITUTE(SUBSTITUTE(SUBSTITUTE(SUBSTITUTE(SUBSTITUTE(SUBSTITUTE(SUBSTITUTE(SUBSTITUTE(SUBSTITUTE(SUBSTITUTE(SUBSTITUTE(SUBSTITUTE(SUBSTITUTE(SUBSTITUTE(SUBSTITUTE(SUBSTITUTE(SUBSTITUTE(SUBSTITUTE(SUBSTITUTE(SUBSTITUTE( IF(--MID(TEXT(ABS(D35),"000000000000000"),1,3)=0,"",MID(TEXT(ABS(D35),"000000000000000"),1,1)&" ratus "&MID(TEXT(ABS(D35),"000000000000000"),2,1)&" puluh "&MID(TEXT(ABS(D35),"000000000000000"),3,1)&" trilyun ")& IF(--MID(TEXT(ABS(D35),"000000000000000"),4,3)=0,"",MID(TEXT(ABS(D35),"000000000000000"),4,1)&" ratus "&MID(TEXT(ABS(D35),"000000000000000"),5,1)&" puluh "&MID(TEXT(ABS(D35),"000000000000000"),6,1)&" milyar ")& IF(--MID(TEXT(ABS(D35),"000000000000000"),7,3)=0,"",MID(TEXT(ABS(D35),"000000000000000"),7,1)&" ratus "&MID(TEXT(ABS(D35),"000000000000000"),8,1)&" puluh "&MID(TEXT(ABS(D35),"000000000000000"),9,1)&" juta ")& IF(--MID(TEXT(ABS(D35),"000000000000000"),10,3)=0,"",IF(--MID(TEXT(ABS(D35),"000000000000000"),10,3)=1,"*",MID(TEXT(ABS(D35),"000000000000000"),10,1)&" ratus "&MID(TEXT(ABS(D35),"000000000000000"),11,1)&" puluh ")&MID(TEXT(ABS(D35),"000000000000000"),12,1)&" ribu ")& IF(--MID(TEXT(ABS(D35),"000000000000000"),13,3)=0,"",MID(TEXT(ABS(D35),"000000000000000"),13,1)&" ratus "&MID(TEXT(ABS(D35),"000000000000000"),14,1)&" puluh "&MID(TEXT(ABS(D35),"000000000000000"),15,1)),1,"satu"),2,"dua"),3,"tiga"),4,"empat"),5,"lima"),6,"enam"),7,"tujuh"),8,"delapan"),9,"sembilan"),"0 ratus",""),"0 puluh",""),"satu puluh 0","sepuluh"),"satu puluh satu","sebelas"),"satu puluh dua","dua belas"),"satu puluh tiga","tiga belas"),"satu puluh empat","empat belas"),"satu puluh lima","lima belas"),"satu puluh enam","enam belas"),"satu puluh tujuh","tujuh belas"),"satu puluh delapan","delapan belas"),"satu puluh sembilan","sembilan belas"),"satu ratus","seratus"),"*satu ribu","seribu"),0,""))," "," ")) & " rupiah" -> empat ratus sembilan puluh ribu rupiah | F35: =REPLACE(E35,1,1,UPPER(LEFT(E35))) -> Empat ratus sembilan puluh ribu rupiah
A37: Undangan | B37: Nomor | C37: : | F37: HARUS kosong apabila tidak ada undangan
B38: Tanggal | C38: : | F38: tanggal yang tertera di undangan
A40: Laporan | B40: Hasil yang diperoleh | C40: : | D40: TULISKAN LAPORAN DI SHEET LAPORAN v2
B41: Kendala | C41: :
B42: Solusi | C42: :
A45: Penanggung Jawab Kegiatan | C45: : | D45: Khoirul Anwar, S.Tr.Stat.
A46: NIK | C46: : | D46: =VLOOKUP(MATCH(D45,DB!$D$2:$D$14,0),DB!$A$2:$H$14,3) -> 19990307 202104 1 001
...

Sheet DB
A1: no | B1: id | C1: id2 | D1: nama | E1: jabatan | F1: pangkat | G1: golongan | H1: email
A2: 1 | B2: 340016793 | C2: 19780715 200212 1 006 | D2: Restu Kristianto, S.Pi. | E2: Kepala BPS Kabupaten/Kota | F2: Penata Tk. I | G2: III/d | H2: restukris@bps.go.id
A3: 2 | B3: 340056564 | C3: 19870623 201403 2 002 | D3: Yektining Asih Rahayu, S.Si. | E3: Kepala Subbagian Umum | F3: Penata | G3: III/c | H3: yektining@bps.go.id
A4: 3 | B4: 340055334 | C4: 19771027 201101 1 002 | D4: Willo Friody, S.P. | E4: Statistisi Ahli Muda | F4: Penata Tk. I | G4: III/d | H4: willo@bps.go.id
A5: 4 | B5: 340062829 | C5: 19881210 202421 1 004 | D5: Fransiska, A.Md. | E5: Pranata Komputer Pelaksana/Terampil | F5: Pengatur | G5: II/c | H5: fransiska-pppk@bps.go.id
A6: 5 | B6: 340057652 | C6: 19930505 201602 2 002 | D6: Yoviana Yulta, SST. | E6: Statistisi Ahli Muda | F6: Penata | G6: III/c | H6: yoviana@bps.go.id
A7: 6 | B7: 340060172 | C7: 19970409 202104 1 002 | D7: Krishna Aji Satriatama, S.Tr.Stat. | E7: Pranata Komputer Ahli Pertama | F7: Penata Muda Tk. I | G7: III/b | H7: krishna.aji@bps.go.id
A8: 7 | B8: 340060821 | C8: 19970731 202201 1 001 | D8: Noor Supriyadi, S.Tr.Stat. | E8: Statistisi Ahli Pertama | F8: Penata Muda | G8: III/a | H8: noor.supriyadi@bps.go.id
A9: 8 | B9: 340060184 | C9: 19980831 202104 1 001 | D9: Luthfan Shaoti, S.Tr.Stat. | E9: Statistisi Ahli Pertama | F9: Penata Muda Tk. I | G9: III/b | H9: luthfan.shaoti@bps.go.id
A10: 9 | B10: 340060169 | C10: 19990307 202104 1 001 | D10: Khoirul Anwar, S.Tr.Stat. | E10: Statistisi Ahli Pertama | F10: Penata Muda Tk. I | G10: III/b | H10: anwar.khoirul@bps.go.id
A11: 10 | B11: 340060762 | C11: 19990424 202201 1 004 | D11: Mikha Aprilio, S.Tr.Stat. | E11: Statistisi Ahli Pertama | F11: Penata Muda | G11: III/a | H11: mikha.aprilio@bps.go.id
A12: 11 | B12: 340060431 | C12: 19990712 202104 2 001 | D12: Tiara Andansari, A.Md.Stat | E12: Statistisi Pelaksana/Terampil | F12: Pengatur Tk. I | G12: II/d | H12: tiara.andansari@bps.go.id
A13: 12 | B13: 340062021 | C13: 19991011 202302 2 001 | D13: Rifatul Mina, S.Tr.Stat. | E13: Statistisi Ahli Pertama | F13: Penata Muda | G13: III/a | H13: rifatul.mina@bps.go.id
A14: 13 | B14: 340062401 | C14: 19991017 202310 2 001 | D14: Diah Aisyah, S.Tr.Stat. | E14: Statistisi Ahli Pertama | F14: Penata Muda | G14: III/a | H14: diah.aisyah@bps.go.id
A15: 14 | B15: 340063024 | C15: 200205082024121002 | D15: Angga Jati Mandiri, S.Tr.Stat. | E15: Statistisi Ahli Pertama | F15: Penata Muda | G15: III/a | H15: angga.jati@bps.go.id
A16: 15 | B16: 340063196 | C16: 200107112024121002 | D16: Haidar Hilmy Ahmady, S.Tr.Stat. | E16: Pranata Komputer Ahli Pertama | F16: Penata Muda | G16: III/a | H16: haidar.hilmy@bps.go.id
A17: 16 | B17: 340063423 | C17: 200008012024122001 | D17: Nurwidati Puspita, S.Tr.Stat. | E17: Statistisi Ahli Pertama | F17: Penata Muda | G17: III/a | H17: nurwidati.puspita@bps.go.id
A18: 17 | B18: 340063579 | C18: 200112232024122002 | D18: Vivi Dewita Sari, S.Tr.Stat. | E18: Statistisi Ahli Pertama | F18: Penata Muda | G18: III/a | H18: vividewitas@bps.go.id
A19: 18
A20: 19
A21: 20
A22: 21
A23: 22
A24: 23
A25: 24
A26: 25
A27: 26
A28: 27
A29: 28
A30: 29
A31: 30
A46: Date Conversion
A47: no | B47: date1 | C47: date2
A48: 1 | B48: Januari | C48: January
A49: 2 | B49: Februari | C49: February
A50: 3 | B50: Maret | C50: March
A51: 4 | B51: April | C51: April
A52: 5 | B52: Mei | C52: May
A53: 6 | B53: Juni | C53: June
A54: 7 | B54: Juli | C54: July
...

Sheet ST
C4: Kepala BPS Kabupaten Murung Raya
C5: Kabupaten Murung Raya
C7: SURAT TUGAS
C8: =CONCATENATE("Nomor : ",DATA!D1) -> Nomor : B-1122/62130/KU.340/2026
C9: Menimbang | D9: : | E9: 1. | F9: Berdasarkan Peraturan Gubernur Provinsi Kalimantan Tengah Nomor 188.44/94/2020 Tahun 2020 tentang Pembatasan Kegiatan Bepergian Keluar dan/atau Masuk Provinsi Kalimantan Tengah Dalam Upaya Pencegahan Penyebaran Corona Virus Disease 2019 (COVID-19);
E10: 2. | F10: Bahwa berdasarkan pertimbangan tersebut di atas, perlu memberikan surat tugas kepada Pegawai Negeri Sipil yang namanya tercantum di bawah ini;
C12: Mengingat | D12: : | E12: 1. | F12: Undang-Undang Nomor 5 Tahun 2014 tentang Aparatur Sipil Negara;
E13: 2. | F13: Peraturan Pemerintah Nomor 11 Tahun 2017 tentang Manajemen Pegawai Negeri Sipil sebagaimana telah diubah dengan Peraturan Pemerintah Nomor 17 Tahun 2020;
E14: 3. | F14: Peraturan Pemerintah Nomor 21 Tahun 2020 tentang Pembatasan Sosial Berskala Besar Dalam Rangka Percepatan Penanganan Corona Virus Disease (COVID-19);
E15: 4. | F15: Peraturan Menteri Kesehatan Nomor 9 Tahun 2020 tentang Pedoman Pembatasan Sosial Berskala Besar Dalam Rangka Percepatan Penanganan Corona Virus Disease (COVID-19);
E16: 5. | F16: Peraturan Gubernur Provinsi Kalimantan Tengah Nomor 188.44/94/2020 Tahun 2020 tentang Pembatasan Kegiatan Bepergian Keluar dan/atau Masuk Provinsi Kalimantan Tengah Dalam Upaya Pencegahan Penyebaran Corona Virus Disease 2019 (COVID-19);
C18: Memberi Perintah :
C20: Kepada | D20: : | E20: 1. | F20: =+CONCATENATE(DATA!D6," ; NIP. ",DATA!D7,"; Jabatan : ", DATA!D8) -> Luthfiani Nur Aisyah, S.Tr.Stat. ; NIP. 20030629 202603 2 001; Jabatan : Pelaksana
C22: Untuk | D22: : | E22: 1. | F22: =+CONCATENATE("Untuk melaksanakan tugas pada Seksi Statistik Sosial BPS Kabupaten Murung Raya yang beralamat di jalan Pangeran Diponegoro (Komplek Kantor Pemda) Puruk Cahu, Mulai Tanggal ", DATA!D12) -> Untuk melaksanakan tugas pada Seksi Statistik Sosial BPS Kabupaten Murung Raya yang beralamat di jalan Pangeran Diponegoro (Komplek Kantor Pemda) Puruk Cahu, Mulai Tanggal 15 Agustus 2026 s.d. 15 Agustus 2026
E23: 2. | F23: =+CONCATENATE("Melakukan ",DATA!D11,) -> Melakukan Melakukan Pengawasan Pendataan Sakernas Agustus 2026 di Desa Juking Supan
C24: =CONCATENATE("Puruk Cahu, ",DATA!D2) -> Puruk Cahu, 13 Agustus 2026
H25: =DATA!D4 -> Kepala BPS Kabupaten Murung Raya
H29: =DATA!D3 -> Restu Kristianto, S.Pi.
C33: Jl. Pangeran Diponegoro, Puruk Cahu 73911 (Komplek Kantor Pemda)
C34: Telp. : (0528) 3033022, Website: http://murakab.bps.go.id E-mail:bps6213@bps.go.id

Sheet SPD
E2: BADAN PUSAT STATISTIK
E3: PROVINSI KALIMANTAN TENGAH | I3: Lembar | J3: :
E4: Jl. Kpt. Piere Tendean No.6 Palangka Raya | I4: Nomor | J4: : | K4: =+DATA!D15 -> 231/62130/KU.340/2026
C5: SURAT PERJALANAN DINAS
C6: 1 | D6: Kuasa Pengguna Anggaran | G6: =+DATA!D25 -> Khoirul Anwar, S.Tr.Stat.
C7: 2 | D7: Nama/NIP Pegawai yang melaksanakan perjalanan dinas | G7: =CONCATENATE(DATA!D6," / NIP. ",DATA!D7) -> Luthfiani Nur Aisyah, S.Tr.Stat. / NIP. 20030629 202603 2 001
C8: 3 | D8: a. Pangkat dan Golongan | G8: a. | H8: =IF(+DATA!D9=0,"",+DATA!D9) -> Penata Muda / III/a
D9: b. Jabatan/Instansi | G9: b. | H9: =+CONCATENATE(DATA!D8," BPS Kabupaten Murung Raya") -> Pelaksana BPS Kabupaten Murung Raya
D10: c. Tingkat Biaya PerjalananDinas | G10: c. | H10: C
C11: 4 | D11: Maksud Perjalanan Dinas | G11: =ST!F23 -> Melakukan Melakukan Pengawasan Pendataan Sakernas Agustus 2026 di Desa Juking Supan
C14: 5 | D14: Alat angkutan yang dipergunakan | G14: =+DATA!D17 -> Kendaraan Air
C15: 6 | D15: a. Tempat Berangkat | G15: a. | H15: =+DATA!D19 -> Kabupaten Murung Raya
D16: b. Tempat Tujuan | G16: b. | H16: =+DATA!D21 -> Kabupaten Murung Raya
C17: 7 | D17: a. Lamanya Perjalanan Dinas | G17: a. | H17: =CONCATENATE(DATA!E22," (",DATA!F22,") hari") -> 1 (satu) hari
D18: b. Tanggal Berangkat | G18: b. | H18: =IF(+DATA!D23=0,"",+DATA!D23) -> 15 Agustus 2026
D19: c. Tanggal harus kembali/Tiba di tempat baru | G19: c. | H19: =IF(+DATA!D24=0,"",+DATA!D24) -> 15 Agustus 2026
C20: 8 | D20: Pengikut : | F20: Umur | G20: Hubungan keluarga | K20: Keterangan
D21: 1.
D22: 2.
C23: 9 | D23: Pembebanan anggaran :
D24: a. Instansi | G24: Badan Pusat Statistik Provinsi Kalimantan Tengah
D25: b. Kegiatan / Mata Anggaran Kegiatan (MAK) | G25: 524113 (Belanja Perjalanan Dinas Dalam Kota)
G26: =+DATA!D13 -> GG.2905.BMA.004.052.A.524113
C27: 10 | D27: Keterangan Lain-Lain | G27: =CONCATENATE("Surat Tugas Nomor: ",DATA!D1) -> Surat Tugas Nomor: B-1122/62130/KU.340/2026
I29: Dikeluarkan di : Puruk Cahu
I30: =CONCATENATE("Pada tanggal : ",DATA!D16) -> Pada tanggal : 13 Agustus 2026
I32: BPS Kabupaten Murung Raya
I33: =+DATA!D26 -> Pejabat Pembuat Komitmen
I37: =+G6 -> Khoirul Anwar, S.Tr.Stat.
I38: =CONCATENATE("NIP. ",DATA!D27) -> NIP. 19990307 202104 1 001

Sheet Kuitansi
C3: Pro/Keg/Output | D3: : | E3: =DATA!D13 -> GG.2905.BMA.004.052.A.524113 | H3: Dibukukan
C4: TA | D4: : | E4: 2024 | H4: Tanggal :
H5: Nomor :
C6: K U I T A N S I
C8: Sudah terima dari | E8: : | F8: Pejabat Pembuat Komitmen BPS Kabupaten Murung Raya
C9: Uang Sebanyak | E9: : | F9: =CONCATENATE("Rp. ",TEXT(DATA!D35,"#"),",-") -> Rp. 490000,-
C10: Untuk pembayaran | E10: : | F10: =CONCATENATE("Biaya ",DATA!D11,", tanggal ",DATA!D12,", sesuai dengan :") -> Biaya Melakukan Pengawasan Pendataan Sakernas Agustus 2026 di Desa Juking Supan, tanggal 15 Agustus 2026 s.d. 15 Agustus 2026, sesuai dengan :
F13: =CONCATENATE("Surat Tugas Nomor: ",DATA!D1," tanggal ",DATA!D2) -> Surat Tugas Nomor: B-1122/62130/KU.340/2026 tanggal 13 Agustus 2026
F14: =IF(OR(DATA!$D$15="-",DATA!$D$16="-"),"SPD Nomor: -","SPD Nomor: "&DATA!$D$15&", tanggal "&DATA!$D$16) -> SPD Nomor: 231/62130/KU.340/2026, tanggal 13 Agustus 2026
C16: Terbilang | E16: : | F16: =CONCATENATE("** ",DATA!F35," **") -> ** Empat ratus sembilan puluh ribu rupiah **
C19: Mengetahui : | G19: Lunas pada tanggal : | H19: ="Puruk Cahu, "&DATA!D29 -> Puruk Cahu, 18 Agustus 2026
C21: An. Kuasa Pengguna Anggaran | G21: Bendahara Pengeluaran/PUMC
C22: Pejabat Pembuat Komitmen | G22: BPS Kabupaten Murung Raya | H22: Yang menerima
C23: BPS Kabupaten Murung Raya
C27: =DATA!D25 -> Khoirul Anwar, S.Tr.Stat. | G27: =DATA!D49 -> Tiara Andansari, A.Md.Stat | H27: =DATA!D6 -> Luthfiani Nur Aisyah, S.Tr.Stat.
C28: ="NIP. "&DATA!D27 -> NIP. 19990307 202104 1 001 | G28: ="NIP. "&DATA!D50 -> NIP. 19990712 202104 2 001 | H28: =CONCATENATE("NIP. ",DATA!D7) -> NIP. 20030629 202603 2 001
C29: Barang/pekerjaan tersebut telah diterima/diselesaikan dengan lengkap dan baik
G30: =DATA!D47 -> Pejabat Pembuat Komitmen BPS Kabupaten Murung Raya
G35: =DATA!D45 -> Khoirul Anwar, S.Tr.Stat.
G36: ="NIP. "&DATA!D46 -> NIP. 19990307 202104 1 001

Sheet Kuitansi v2
G3: Tahun Anggaran | H3: : | I3: =RIGHT(DATA!D1,4) -> 2026
G4: Nomor Bukti | H4: :
G5: Akun | H5: : | I5: =DATA!D13 -> GG.2905.BMA.004.052.A.524113
G6: Kepada | H6: : | I6: =DATA!D6 -> Luthfiani Nur Aisyah, S.Tr.Stat.
G7: Satker | H7: : | I7: 668650 - Badan Pusat Statistik Kabupaten Murung Raya
B10: Kuitansi/Bukti Pembayaran
B12: Sudah terima dari | D12: : | E12: Pejabat Pembuat Komitmen BPS Kabupaten Murung Raya
B13: Jumlah Uang | D13: : | E13: =Kuitansi!F9 -> Rp. 490000,-
B14: Terbilang | D14: : | E14: =Kuitansi!F16 -> ** Empat ratus sembilan puluh ribu rupiah **
B16: Kuitansi Supplier | D16: : | E16: -
B17: Untuk pembayaran | D17: : | E17: ="Biaya perjalanan dinas dalam rangka "&DATA!D11&", tanggal "&DATA!D23&", sesuai dengan:" -> Biaya perjalanan dinas dalam rangka Melakukan Pengawasan Pendataan Sakernas Agustus 2026 di Desa Juking Supan, tanggal 15 Agustus 2026, sesuai dengan:
E20: ="Surat Tugas Nomor: "&DATA!D1&" tanggal "&DATA!D2 -> Surat Tugas Nomor: B-1122/62130/KU.340/2026 tanggal 13 Agustus 2026
E21: =IF(DATA!D15<>"",_xlfn.CONCAT("SPD Nomor: ",DATA!D15," tanggal ",DATA!D16),"") -> SPD Nomor: 231/62130/KU.340/2026 tanggal 13 Agustus 2026
H24: ="Puruk Cahu, "&DATA!D29 -> Puruk Cahu, 18 Agustus 2026
H25: Yang menerima
H29: =DATA!D6 -> Luthfiani Nur Aisyah, S.Tr.Stat.
H30: ="NIP. "&DATA!D7 -> NIP. 20030629 202603 2 001
B32: An. Kuasa Pengguna Anggaran | H32: Lunas dibayar,
B33: Pejabat Pembuat Komitmen | H33: Bendahara Pengeluaran
B37: =DATA!D25 -> Khoirul Anwar, S.Tr.Stat. | H37: =DATA!D49 -> Tiara Andansari, A.Md.Stat
B38: ="NIP. "&DATA!D27 -> NIP. 19990307 202104 1 001 | H38: ="NIP. "&DATA!D50 -> NIP. 19990712 202104 2 001
B40: Barang/pekerjaan tersebut telah diterima/diselesaikan dengan lengkap dan baik
B41: Pejabat yang bertanggungjawab
B42: Pejabat Pembuat Komitmen
B46: =B37 -> Khoirul Anwar, S.Tr.Stat.
B47: ="NIP. "&DATA!D46 -> NIP. 19990307 202104 1 001

Sheet Rincian
C2: PERINCIAN PERHITUNGAN BIAYA PERJALANAN DINAS
D4: Lampiran SPD Nomor | F4: : | G4: =IF(DATA!D15=0,"-",DATA!D15) -> 231/62130/KU.340/2026
D5: Tanggal | F5: : | G5: =IF(DATA!D15=0,"-",DATA!D16) -> 13 Agustus 2026
C7: No | D7: Perincian Biaya | J7: Jumlah | L7: Keterangan
C8: 1 | D8: a. Nama yang bertugas | F8: : | G8: =DATA!D6 -> Luthfiani Nur Aisyah, S.Tr.Stat.
D9: b. Pangkat/Gol | F9: : | G9: =DATA!D9 -> Penata Muda / III/a
D10: c. Tujuan tugas | F10: : | G10: =DATA!D21 -> Kabupaten Murung Raya
D11: d. Lamanya tugas | F11: : | G11: =DATA!D22 -> 1 (satu) hari
C12: 2 | D12: Transport | F12: : | G12: ="dari "&DATA!D18&" ke "&DATA!D20 -> dari Kelurahan Beriwit ke Desa Juking Supan | J12: Rp. | K12: =DATA!D31 -> 0 | O12: < ISIKAN TUJUAN DAN NOMINAL TRANSPORT
C14: 3 | D14: Uang harian perjadin | F14: : | G14: =G11 -> 1 (satu) hari | H14: =CONCATENATE("x Rp.",TEXT(DATA!D30,"#.00"),",-") -> x Rp.140.000,- | J14: Rp. | K14: =DATA!D30*DATA!E22 -> 140000
A15: >>>>>>> | C15: 4 | D15: Penginapan | F15: : | G15: 1 (satu) malam | H15: x Rp. 0,- | J15: Rp. | K15: =DATA!D33 -> 0 | O15: < PENGINAPAN HANYA JIKA MENGGUNAKAN AKOMODASI, ISIKAN DURASI SESUAI DENGAN LEMBAR VISUM
C16: 5 | D16: Pengeluaran Rill | F16: : | J16: Rp. | K16: =Riil!I20 -> 350000 | O16: < TRANSPORT LOKAL MASUK KE PENGELUARAN RIIL
D17: JUMLAH | J17: Rp. | K17: =SUM(K12:K16) -> 490000
D18: =+Kuitansi!F16 -> ** Empat ratus sembilan puluh ribu rupiah **
I20: =Kuitansi!H19 -> Puruk Cahu, 18 Agustus 2026
D22: Telah dibayar sejumlah: | I22: Telah menerima jumlah uang sebesar:
D23: =+I23 -> Rp. 490000 | I23: =CONCATENATE(J17," ",K17) -> Rp. 490000
D25: Lunas pada tanggal:
D27: Bendahara Pengeluaran/PUMC | J27: Yang Menerima,
D28: BPS Kabupaten Murung Raya
D32: =Kuitansi!G27 -> Tiara Andansari, A.Md.Stat | J32: =+Kuitansi!H27 -> Luthfiani Nur Aisyah, S.Tr.Stat.
D33: =Kuitansi!G28 -> NIP. 19990712 202104 2 001 | J33: =+Kuitansi!H28 -> NIP. 20030629 202603 2 001
C35: PERHITUNGAN SPD RAMPUNG
D37: Ditetapkan sejumlah | F37: : | G37: Rp. | H37: =+K17 -> 490000
D38: Yang telah dibayar semula | F38: : | G38: Rp. | H38: 0,-
D39: Sisa kurang / lebih | F39: : | G39: Rp. | H39: =+H37 -> 490000
J43: Pejabat Pembuat Komitmen
J44: BPS Kabupaten Murung Raya
J47: =Kuitansi!C27 -> Khoirul Anwar, S.Tr.Stat.
J48: =Kuitansi!C28 -> NIP. 19990307 202104 1 001

Sheet Riil
C2: DAFTAR PENGELUARAN RIIL
C5: Yang bertanda tangan dibawah ini :
D7: Nama | E7: : | F7: =DATA!D6 -> Luthfiani Nur Aisyah, S.Tr.Stat.
D8: NIP | E8: : | F8: =DATA!D7 -> 20030629 202603 2 001
D9: Jabatan | E9: : | F9: =DATA!D8 -> Pelaksana
C10: =IF(DATA!D15<>"",_xlfn.CONCAT("Berdasarkan ",Kuitansi!F14,". Dengan ini kami menyatakan dengan sesungguhnya bahwa:"),_xlfn.CONCAT("Berdasarkan ",'Kuitansi v2'!E20:J20,". Dengan ini kami menyatakan dengan sesungguhnya bahwa:")) -> Berdasarkan SPD Nomor: 231/62130/KU.340/2026, tanggal 13 Agustus 2026. Dengan ini kami menyatakan dengan sesungguhnya bahwa:
C14: 1. | D14: Biaya transport pegawai dan/atau biaya penginapan dibawah ini yang tidak dapat diperoleh bukti-bukti pengeluarannya, meliputi:
C17: No | D17: URAIAN | H17: JUMLAH (Rp)
C18: 1 | D18: Biaya transportasi air dari Kelurahan Beriwit ke Desa Juking Supan PP | H18: Rp. | I18: 350000 | L18: < ISIKAN RINCIAN PENGELUARAN
D19: Sesuai SK Kuasa Pengguna Anggaran BPS Kabupaten Murung Raya Nomor 14 Tahun 2026 Tanggal 7 Januari 2026 Tentang Besaran Biaya Transport Perjalanan Dinas Dalam Kota Tahun Anggaran 2026
D20: Jumlah | H20: Rp. | I20: =SUM(I18:I19) -> 350000
C22: 2. | D22: Jumlah uang tersebut pada angka di atas benar-benar dikeluarkan untuk pelaksanaan perjalanan dinas dimaksud dan apabila dikemudian hari terdapat kelebihan atas pembayaran, kami bersedia untuk menyetorkan kelebihan tersebut ke Kas Negara.
C26: Demikian pernyataan ini kami buat dengan sebenarnya, untuk dipergunakan sebagaimana mestinya .
G29: =Rincian!I20 -> Puruk Cahu, 18 Agustus 2026
C31: Mengetahui /Menyetujui
C32: An. Kuasa Pengguna Anggaran | G32: Pejabat Negara/ Pegawai Negeri
C33: Pejabat Pembuat Komitmen | G33: Yang melakukan Perjalanan Dinas
C34: BPS Kabupaten Murung Raya
C37: =Kuitansi!C27 -> Khoirul Anwar, S.Tr.Stat. | G37: =F7 -> Luthfiani Nur Aisyah, S.Tr.Stat.
C38: =Kuitansi!C28 -> NIP. 19990307 202104 1 001 | G38: =Rincian!J33 -> NIP. 20030629 202603 2 001
I43: 0

Sheet Laporan
E2: BADAN PUSAT STATISTIK
E3: KABUPATEN MURUNG RAYA
B6: Kepada Yth. | F6: : | G6: Kepala BPS Kabupaten Murung Raya
B7: Dari | F7: : | G7: =DATA!D6&" ("&DATA!D8&")" -> Luthfiani Nur Aisyah, S.Tr.Stat. (Pelaksana)
B9: Unit Kerja | F9: : | G9: BPS Kabupaten Murung Raya
B11: LAPORAN PERJALANAN DINAS
B13: I. | C13: DASAR
C14: a. | D14: =+Kuitansi!F13 -> Surat Tugas Nomor: B-1122/62130/KU.340/2026 tanggal 13 Agustus 2026
C15: b. | D15: =+Kuitansi!F14 -> SPD Nomor: 231/62130/KU.340/2026, tanggal 13 Agustus 2026
B17: II. | C17: MAKSUD DAN TUJUAN
C18: =DATA!D11 -> Melakukan Pengawasan Pendataan Sakernas Agustus 2026 di Desa Juking Supan
B20: III. | C20: WAKTU DAN TEMPAT PELAKSANAAN
C21: =CONCATENATE("Kegiatan dilaksanakan di ",DATA!D21," selama ",DATA!D22,", pada tanggal ",DATA!D12,"") -> Kegiatan dilaksanakan di Kabupaten Murung Raya selama 1 (satu) hari, pada tanggal 15 Agustus 2026 s.d. 15 Agustus 2026
B24: IV. | C24: HASIL YANG DIPEROLEH
C25: =DATA!D40 -> TULISKAN LAPORAN DI SHEET LAPORAN v2
B28: V. | C28: KENDALA/HAMBATAN YANG DIHADAPI DAN SOLUSI UNTUK MENGATASI PERMASALAHAN
C30: Kendala :
C31: =DATA!D41 -> 0
C34: Solusi :
C35: =DATA!D42 -> 0
B37: Demikian laporan ini saya sampaikan, atas perhatian dan kerjasamanya disampaikan terimakasih.
B40: =Riil!G29 -> Puruk Cahu, 18 Agustus 2026 | H40: Mengetahui,
B41: Yang menyampaikan laporan | H41: =DATA!D4 -> Kepala BPS Kabupaten Murung Raya
B44: =+Riil!G37 -> Luthfiani Nur Aisyah, S.Tr.Stat. | H44: =DATA!D3 -> Restu Kristianto, S.Pi.
B45: =+Riil!G38 -> NIP. 20030629 202603 2 001 | H45: ="NIP. "&DATA!D5 -> NIP. 19780715 200212 1 006

Sheet Laporan v2
E2: LAPORAN HASIL PERJALANAN DINAS
B4: Kepada Yth. | D4: : | E4: Kepala BPS Kabupaten Murung Raya
B5: Perihal | D5: : | E5: =_xlfn.CONCAT("Laporan Perjalanan Dinas untuk ",DATA!D10) -> Laporan Perjalanan Dinas untuk Pengawasan Pendataan Sakernas Agustus 2026
B8: I. | C8: Pelaksana Perjalanan
E9: Nama | F9: : | G9: =DATA!D6 -> Luthfiani Nur Aisyah, S.Tr.Stat.
E10: NIP | F10: : | G10: =DATA!D7 -> 20030629 202603 2 001
E11: Jabatan | F11: : | G11: =DATA!D8 -> Pelaksana
B13: II. | C13: Dasar Pelaksanaan
E14: Nomor Surat Tugas | F14: : | G14: =_xlfn.CONCAT(DATA!D1," tanggal ",DATA!D2) -> B-1122/62130/KU.340/2026 tanggal 13 Agustus 2026
E15: =IF(DATA!D15<>"","Nomor SPD","") -> Nomor SPD | F15: =IF(DATA!D15<>"",":","") -> : | G15: =IF(DATA!D15<>"",_xlfn.CONCAT(DATA!D15," tanggal ",DATA!D16),"") -> 231/62130/KU.340/2026 tanggal 13 Agustus 2026
E16: =IF(DATA!D37<>"","Surat Undangan","") | F16: =IF(DATA!D37<>"",":","") | G16: =IF(DATA!D37<>"",_xlfn.CONCAT(DATA!D37," tanggal ",DATA!D38),"")
B18: III. | C18: Tujuan Perjalanan Dinas | D18: : | E18: =DATA!D11 -> Melakukan Pengawasan Pendataan Sakernas Agustus 2026 di Desa Juking Supan
B20: IV. | C20: Daerah Tujuan/Instansi | D20: : | E20: =_xlfn.CONCAT("Desa ",DATA!D20,", ",DATA!D21) -> Desa Desa Juking Supan, Kabupaten Murung Raya
B22: V. | C22: Waktu Pelaksanaan | D22: : | E22: =DATA!D12 -> 15 Agustus 2026 s.d. 15 Agustus 2026
B24: VI. | C24: Kesimpulan Hasil Kegiatan | D24: : | E24: Telah melaksanakan pendampingan dan pengawasan pemutakhiran Survei Angkatan Kerja Nasional (SAKERNAS) di Desa Muara Joloi I. Keberangkatan dilakukan pada hari Senin, 26 Januari 2026 bersama petugas menggunakan transportasi darat pada pukul 09.00. Perjalanan dilakukan selama 6 jam dan sampai di Desa Muara Joloi I pada pukul 15.00. Setelah sampai, langsung dilakukan pemutakhiran dengan cara door-to-door di RT.03 dibantu oleh Ketua RT setempat. Ditemukan beberapa rumah yang hanya dijadikan rumah singgah oleh penduduk yang tinggal di RT.01 dan rumah baru yang ditinggali oleh keluarga baru. Pemutakhiran dilakukan dengan lancar dan sesuai dengan prosedur sebelum pukul 18.00, kemudian menyebrang sungai menuju RT.01 untuk memesan akomodasi selama satu malam. Pada esok pagi dilakukan pemeriksaaan dokumen dan melengkapi isian formulir di FASIH yang belum lengkap. Kemudian pada pukul 11.00 melakukan perjalalanan pulang ke Puruk Cahu dan sampai pada pukul 17.00.
B29: VII. | C29: Tindak Lanjut | D29: : | E29: Hal-hal yang perlu diperhatikan antara lain:
E30: 1. Pemeriksaan perlu dilakukan di aplikasi FASIH dan melakukan proses approval untuk menandai pekerjaan yang sudah benar
E31: 2. Memeriksa hasil pekerjaan di SLS kedua di Desa Bahitom, dan apabila sudah selesai untuk menandari pemutakhiran di kedua SLS ke status selesai.
E32: 3. Memonitor hasil pekerjaan secara keseluruhan, menarik sampel untuk pendataan, dan melakukan pembuatan jadwal pengawasan kegiatan pendataan bersama petugas yang sama.
B34: Demikian Laporan Perjalanan Dinas ini dibuat sebagai bahan Laporan.
B37: Mengetahui, | H37: =Riil!G29 -> Puruk Cahu, 18 Agustus 2026
B38: =DATA!D4 -> Kepala BPS Kabupaten Murung Raya | H38: Pelaksana Perjalanan Dinas
B41: =DATA!D3 -> Restu Kristianto, S.Pi. | H41: =DATA!D6 -> Luthfiani Nur Aisyah, S.Tr.Stat.
B42: ="NIP. "&DATA!D5 -> NIP. 19780715 200212 1 006 | H42: ="NIP. "&DATA!D7 -> NIP. 20030629 202603 2 001

Sheet >8 Jam
B4: SURAT PERNYATAAN
B5: PERJALANAN DINAS DALAM KOTA LEBIH DARI 8 JAM
B7: Yang bertanda tangan di bawah ini :
B8: Nama | D8: : | E8: =DATA!D6 -> Luthfiani Nur Aisyah, S.Tr.Stat.
B9: NIP | D9: : | E9: =DATA!D7 -> 20030629 202603 2 001
B10: Jabatan | D10: : | E10: =DATA!D8 -> Pelaksana | M10: HANYA ISI JIKA PERJADIN LEBIH DARI 8 JAM DAN TIDAK MENGINAP
B12: Dengan ini menyatakan bahwa perjalanan dinas dalam kota yang saya laksanakan sebagai berikut :
B13: a. | C13: Nomor Surat Tugas | D13: : | E13: =_xlfn.CONCAT(DATA!D1,", tanggal ",DATA!D2) -> B-1122/62130/KU.340/2026, tanggal 13 Agustus 2026
B14: b. | C14: Nomor SPD | D14: : | E14: =IF(DATA!D15<>"",_xlfn.CONCAT(DATA!D15,", tanggal ",DATA!D16),"-") -> 231/62130/KU.340/2026, tanggal 13 Agustus 2026
B15: c. | C15: Tujuan | D15: : | E15: =_xlfn.CONCAT(DATA!D11," selama ",DATA!D22," pada tanggal 15 Agustus 2026") -> Melakukan Pengawasan Pendataan Sakernas Agustus 2026 di Desa Juking Supan selama 1 (satu) hari pada tanggal 15 Agustus 2026
M19: < ISIKAN RINCIAN PERJALANAN
B24: Adalah benar dilaksanakan lebih dari 8 jam.
B25: Demikian pernyataan ini dibuat dengan sebenar-benarnya, dan saya sanggup menerima konsekuensi jika pernyataan ini tidak benar.
H27: =Kuitansi!H19 -> Puruk Cahu, 18 Agustus 2026
B28: Mengetahui,
B29: BPS Kabupaten Murung Raya
B30: Pejabat Pembuat Komitmen, | H30: Pelaksana Perjalanan Dinas,
B34: =Kuitansi!C27 -> Khoirul Anwar, S.Tr.Stat. | H34: =Kuitansi!H27 -> Luthfiani Nur Aisyah, S.Tr.Stat.
B35: =Kuitansi!C28 -> NIP. 19990307 202104 1 001 | H35: =Kuitansi!H28 -> NIP. 20030629 202603 2 001

Sheet Kendaraan
B4: SURAT PERNYATAAN
B5: TIDAK MENGGUNAKAN KENDARAAN DINAS
B7: Yang bertanda tangan di bawah ini:
B8: Nama | D8: : | E8: =DATA!D6 -> Luthfiani Nur Aisyah, S.Tr.Stat. | M8: HANYA ISI JIKA PERJADIN TIDAK MENGGUNAKAN KENDARAAN DINAS
B9: NIP | D9: : | E9: =DATA!D7 -> 20030629 202603 2 001
B10: Satuan Kerja | D10: : | E10: BPS Kabupaten Murung Raya
B11: Jabatan | D11: : | E11: =DATA!D8 -> Pelaksana
B13: =_xlfn.CONCAT("Menerangkan bahwa dalam rangka melaksanakan perjalanan dinas untuk melaksanankan tugas kedinasan sesuai SPD nomor: ",DATA!D15," saya benar-benar tidak menggunakan kendaraan dinas. Demikian pernyataan ini kami buat dengan sebenar-benarnya untuk dipergunakan sebagaimana mestinya. ","Apabila terdapat kekeliruan dalam pertanggungjawaban dan mengakibatkan kerugian negara, saya bersedia dituntut sesuai peraturan yang berlaku dan mengembalikan biaya transport atau biaya transport lokal yang sudah terlanjur saya terima ke kas negara.") -> Menerangkan bahwa dalam rangka melaksanakan perjalanan dinas untuk melaksanankan tugas kedinasan sesuai SPD nomor: 231/62130/KU.340/2026 saya benar-benar tidak menggunakan kendaraan dinas. Demikian pernyataan ini kami buat dengan sebenar-benarnya untuk dipergunakan sebagaimana mestinya. Apabila terdapat kekeliruan dalam pertanggungjawaban dan mengakibatkan kerugian negara, saya bersedia dituntut sesuai peraturan yang berlaku dan mengembalikan biaya transport atau biaya transport lokal yang sudah terlanjur saya terima ke kas negara.
H29: Puruk Cahu, 18 Agustus 2026
H30: Pelaksana Perjalanan Dinas,
H34: =Kuitansi!H27 -> Luthfiani Nur Aisyah, S.Tr.Stat.
H35: =Kuitansi!H28 -> NIP. 20030629 202603 2 001

Sheet Hotel
B4: SURAT PERNYATAAN
B5: TIDAK MENGINAP DI HOTEL ATAU DI PENYEDIA JASA AKOMODASI LAINNYA
B7: Yang bertanda tangan di bawah ini: | M7: HANYA ISI JIKA MENGINAP BUKAN DI HOTEL
B8: Nama | D8: : | E8: =DATA!D6 -> Luthfiani Nur Aisyah, S.Tr.Stat.
B9: NIP | D9: : | E9: =DATA!D7 -> 20030629 202603 2 001
B10: Pangkat | D10: : | E10: =DATA!D9 -> Penata Muda / III/a
B11: Satuan Kerja | D11: : | E11: BPS Kabupaten Murung Raya
B12: Jabatan | D12: : | E12: =DATA!D8 -> Pelaksana
B14: =_xlfn.CONCAT("Menerangkan bahwa selama melaksanakan perjalanan dinas dalam rangka ",DATA!D11," pada tanggal ",DATA!D12,", saya benar-benar tidak menginap di hotel atau jasa akomodasi komersial lainnya."," Demikian pernyataan ini saya buat dengan sebenar-benarnya untuk dipergunakan sebagaimana mestinya. ","Apabila terdapat kekeliruan dalam pertanggung jawaban SPD dan mengakibatkan kerugian negara, saya"," bersedia dituntut sesuai peraturan yang berlaku dan mengembalikan biaya kompensasi menginap di hotel atau jasa akomodasi komersial lainnya yang sudah terlanjur saya terima ke kas negara.") -> Menerangkan bahwa selama melaksanakan perjalanan dinas dalam rangka Melakukan Pengawasan Pendataan Sakernas Agustus 2026 di Desa Juking Supan pada tanggal 15 Agustus 2026 s.d. 15 Agustus 2026, saya benar-benar tidak menginap di hotel atau jasa akomodasi komersial lainnya. Demikian pernyataan ini saya buat dengan sebenar-benarnya untuk dipergunakan sebagaimana mestinya. Apabila terdapat kekeliruan dalam pertanggung jawaban SPD dan mengakibatkan kerugian negara, saya bersedia dituntut sesuai peraturan yang berlaku dan mengembalikan biaya kompensasi menginap di hotel atau jasa akomodasi komersial lainnya yang sudah terlanjur saya terima ke kas negara.
H30: =Kuitansi!H19 -> Puruk Cahu, 18 Agustus 2026
H31: Pelaksana Perjalanan Dinas,
H35: =Kuitansi!H27 -> Luthfiani Nur Aisyah, S.Tr.Stat.
H36: =Kuitansi!H28 -> NIP. 20030629 202603 2 001

Sheet Keterlambatan
B2: BADAN PUSAT STATISTIK
B3: KABUPATEN MURUNG RAYA
B4: Jl. P. Diponegoro (Komplek Kantor Pemda) 73911 Puruk Cahu, Telp (0528) 3033022
B5: WhatsApp 0811-3205-100, E-mail: bps6213@bps.go.id
F8: SURAT PERNYATAAN
F9: KETERLAMBATAN PENGAJUAN TAGIHAN
B12: Yang bertanda tangan di bawah ini:
B14: Nama | C14: : | D14: =Hotel!E8 -> Luthfiani Nur Aisyah, S.Tr.Stat.
B15: NIP | C15: : | D15: =Hotel!E9 -> 20030629 202603 2 001
B16: Jabatan | C16: : | D16: =Hotel!E12 -> Pelaksana
B18: Dengan ini menyatakan sebagai berikut:
B19: 1. | C19: =_xlfn.CONCAT("Telah terjadi keterlambatan mengajukan hak tagihan kepada Pejabat Pembuat Komitmen (PPK) BPS Kabupaten Murung Raya atas pelaksanaan perjalanan dinas ",DATA!D10," yang telah selesai dilaksanakan pada tanggal ",'Laporan v2'!E22,".") -> Telah terjadi keterlambatan mengajukan hak tagihan kepada Pejabat Pembuat Komitmen (PPK) BPS Kabupaten Murung Raya atas pelaksanaan perjalanan dinas Pengawasan Pendataan Sakernas Agustus 2026 yang telah selesai dilaksanakan pada tanggal 15 Agustus 2026 s.d. 15 Agustus 2026. | L19: FORM PERNYATAAN APABILA PENGAJUAN SPJ MELEBIHI WAKTU BATAS PENYERAHAN SPJ (LEWAT 5 HARI KERJA)
C21: =_xlfn.CONCAT("Berdasarkan ", 'Kuitansi v2'!E20:J20) -> Berdasarkan Surat Tugas Nomor: B-1122/62130/KU.340/2026 tanggal 13 Agustus 2026
C22: =IF(DATA!D15<>"",_xlfn.CONCAT("dan ",'Kuitansi v2'!E21:J21),"") -> dan SPD Nomor: 231/62130/KU.340/2026 tanggal 13 Agustus 2026
B23: 2. | C23: Keterlambatan mengajukan hak tagihan disebabkan oleh ###### | K23: <<<<<<< | L23: ISIKAN KETERANGAN MENGAPA TERLAMBAT
B24: 3. | C24: Selanjutnya saya tidak akan mengalami keterlambatan kembali dalam pengajuan hak tagihan sesuai dengan batas waktu pengajuan hak tagihan kepada Negara yang diatur dalam PMK Nomor 190/PMK.05/2012 tentang Tata Cara Pembayaran dalam Rangka Pelaksanaan Anggaran Pendapatan dan Belanja Negara.
B27: Demikian pernyataan ini dibuat dengan sebenar-benarnya.
G31: =Hotel!H30 -> Puruk Cahu, 18 Agustus 2026
G32: Yang menyatakan,
G36: =Hotel!H35 -> Luthfiani Nur Aisyah, S.Tr.Stat.
G37: =Hotel!H36 -> NIP. 20030629 202603 2 001

Sheet dokumentasi
A1: =CONCATENATE("Dokumentasi ",DATA!D11) -> Dokumentasi Melakukan Pengawasan Pendataan Sakernas Agustus 2026 di Desa Juking Supan
A3: Dokumentasi Kegiatan
A51: Dokumentasi Kegiatan
A95: Dokumentasi Saat Perjalanan
A110: Dokumentasi Tiba di Lokasi
A125: Dokumentasi Kepulangan
A140: Dokumentasi Tiba di Daerah Asal
C155: DOKUMENTASI FOTO SUPIR / STNK / SIM APABILA ADA CARTER/SEWA
A156: Dokumentasi Kelengkapan Transportasi
